Module is experimental. 
config file is: /projects/p30771/dlc_analysis/bottom_tracking_openfield_01-JJM-2020-08-18_2/config.yaml
/home/jma819/.conda/envs/tensorflow-gpu-env/lib/python3.6/site-packages/tensorflow/python/framework/dtypes.py:523: FutureWarning: Passing (type, 1) or '1type' as a synonym of type is deprecated; in a future version of numpy, it will be understood as (type, (1,)) / '(1,)type'.
  _np_qint8 = np.dtype([("qint8", np.int8, 1)])
/home/jma819/.conda/envs/tensorflow-gpu-env/lib/python3.6/site-packages/tensorflow/python/framework/dtypes.py:524: FutureWarning: Passing (type, 1) or '1type' as a synonym of type is deprecated; in a future version of numpy, it will be understood as (type, (1,)) / '(1,)type'.
  _np_quint8 = np.dtype([("quint8", np.uint8, 1)])
/home/jma819/.conda/envs/tensorflow-gpu-env/lib/python3.6/site-packages/tensorflow/python/framework/dtypes.py:525: FutureWarning: Passing (type, 1) or '1type' as a synonym of type is deprecated; in a future version of numpy, it will be understood as (type, (1,)) / '(1,)type'.
  _np_qint16 = np.dtype([("qint16", np.int16, 1)])
/home/jma819/.conda/envs/tensorflow-gpu-env/lib/python3.6/site-packages/tensorflow/python/framework/dtypes.py:526: FutureWarning: Passing (type, 1) or '1type' as a synonym of type is deprecated; in a future version of numpy, it will be understood as (type, (1,)) / '(1,)type'.
  _np_quint16 = np.dtype([("quint16", np.uint16, 1)])
/home/jma819/.conda/envs/tensorflow-gpu-env/lib/python3.6/site-packages/tensorflow/python/framework/dtypes.py:527: FutureWarning: Passing (type, 1) or '1type' as a synonym of type is deprecated; in a future version of numpy, it will be understood as (type, (1,)) / '(1,)type'.
  _np_qint32 = np.dtype([("qint32", np.int32, 1)])
/home/jma819/.conda/envs/tensorflow-gpu-env/lib/python3.6/site-packages/tensorflow/python/framework/dtypes.py:532: FutureWarning: Passing (type, 1) or '1type' as a synonym of type is deprecated; in a future version of numpy, it will be understood as (type, (1,)) / '(1,)type'.
  np_resource = np.dtype([("resource", np.ubyte, 1)])
DLC loaded in light mode; you cannot use any GUI (labeling, relabeling and standalone GUI)
/projects/p30771/dlc_analysis/bottom_tracking_openfield_01-JJM-2020-08-18/training-datasets/iteration-0/UnaugmentedDataSet_bottom_tracking_openfield_01Aug18  already exists!
/projects/p30771/dlc_analysis/bottom_tracking_openfield_01-JJM-2020-08-18/labeled-data/C:\Users\ward5279user\Desktop\acquisition_scripts\acquisition_scripts\07272020_D1mGLuR5_OF_289/CollectedData_JJM.h5  not found (perhaps not annotated)
Annotation data was not found by splitting video paths (from config['video_sets']). An alternative route is taken...
The following folders were found: ['.DS_Store', '07272020_D1mGLuR5_OF_289']
/projects/p30771/dlc_analysis/bottom_tracking_openfield_01-JJM-2020-08-18/labeled-data/.DS_Store/CollectedData_JJM.h5  not found (perhaps not annotated)
Traceback (most recent call last):
  File "run_dlc_openfield.py", line 13, in <module>
    deeplabcut.create_training_dataset(path_config_file)
  File "/home/jma819/DeepLabCut/deeplabcut/generate_training_dataset/trainingsetmanipulation.py", line 573, in create_training_dataset
    Data = merge_annotateddatasets(cfg,project_path,Path(os.path.join(project_path,trainingsetfolder)),windows2linux)
  File "/home/jma819/DeepLabCut/deeplabcut/generate_training_dataset/trainingsetmanipulation.py", line 420, in merge_annotateddatasets
    AnnotationData.to_hdf(filename+'.h5', key='df_with_missing', mode='w')
  File "/home/jma819/.conda/envs/tensorflow-gpu-env/lib/python3.6/site-packages/pandas/core/generic.py", line 2530, in to_hdf
    pytables.to_hdf(path_or_buf, key, self, **kwargs)
  File "/home/jma819/.conda/envs/tensorflow-gpu-env/lib/python3.6/site-packages/pandas/io/pytables.py", line 276, in to_hdf
    path_or_buf, mode=mode, complevel=complevel, complib=complib
  File "/home/jma819/.conda/envs/tensorflow-gpu-env/lib/python3.6/site-packages/pandas/io/pytables.py", line 505, in __init__
    self.open(mode=mode, **kwargs)
  File "/home/jma819/.conda/envs/tensorflow-gpu-env/lib/python3.6/site-packages/pandas/io/pytables.py", line 627, in open
    self._handle = tables.open_file(self._path, self._mode, **kwargs)
  File "/home/jma819/.conda/envs/tensorflow-gpu-env/lib/python3.6/site-packages/tables/file.py", line 320, in open_file
    return File(filename, mode, title, root_uep, filters, **kwargs)
  File "/home/jma819/.conda/envs/tensorflow-gpu-env/lib/python3.6/site-packages/tables/file.py", line 784, in __init__
    self._g_new(filename, mode, **params)
  File "tables/hdf5extension.pyx", line 489, in tables.hdf5extension.File._g_new
tables.exceptions.HDF5ExtError: HDF5 error back trace

  File "H5F.c", line 445, in H5Fcreate
    unable to create file
  File "H5Fint.c", line 1519, in H5F_open
    unable to lock the file
  File "H5FD.c", line 1650, in H5FD_lock
    driver lock request failed
  File "H5FDsec2.c", line 941, in H5FD_sec2_lock
    unable to lock file, errno = 11, error message = 'Resource temporarily unavailable'

End of HDF5 error back trace

Unable to open/create file '/projects/p30771/dlc_analysis/bottom_tracking_openfield_01-JJM-2020-08-18/training-datasets/iteration-0/UnaugmentedDataSet_bottom_tracking_openfield_01Aug18//CollectedData_JJM.h5'
